<?xml version="1.0" encoding="utf-8"?>
<!-- This URDF was automatically created by SolidWorks to URDF Exporter! Originally created by Stephen Brawner (brawner@gmail.com) 
     Commit Version: 1.5.1-0-g916b5db  Build Version: 1.5.7152.31018
     For more information, please see http://wiki.ros.org/sw_urdf_exporter -->
<robot
  name="robot">
  <link name="map">
   </link>
  <link
    name="base_link_Chasis">
    <inertial>
      <origin
        xyz="-0.0112401823918047 0.000443693306025505 0.0601080455071435"
        rpy="0 0 0" />
      <mass
        value="5.34447797641956" />
      <inertia
        ixx="0.0273893594112689"
        ixy="1.69654538422057E-05"
        ixz="-1.08762432056227E-06"
        iyy="0.0269594894054598"
        iyz="8.26864136660382E-08"
        izz="0.0517209464806407" />
    </inertial>
    <visual>
      <origin
        xyz="0 0 0"
        rpy="0 0 0" />
      <geometry>
        <mesh
          filename="package://ensamble_mobile/meshes/base_link_Chasis.STL" />
      </geometry>
      <material
        name="">
        <color
          rgba="0.752941176470588 0.752941176470588 0.752941176470588 1" />
      </material>
    </visual>
    <collision>
      <origin
        xyz="0 0 0"
        rpy="0 0 0" />
      <geometry>
        <mesh
          filename="package://ensamble_mobile/meshes/base_link_Chasis.STL" />
      </geometry>
    </collision>
  </link>
  <link
    name="rear_right_wheel">
    <inertial>
      <origin
        xyz="5.67991416164371E-07 2.82678237431555E-06 -0.0304872070529114"
        rpy="3.14159 0 0" />
      <mass
        value="0.62241947518931" />
      <inertia
        ixx="0.000624907057081948"
        ixy="-3.27878592567662E-09"
        ixz="4.02329903687644E-11"
        iyy="0.000624902314874052"
        iyz="-5.11080571575358E-09"
        izz="0.00114905854450842" />
    </inertial>
    <visual>
      <origin
        xyz="0 0 0"
        rpy="3.14159 0 0" />
      <geometry>
        <mesh
          filename="package://ensamble_mobile/meshes/Link_1_1_wheel.STL" />
      </geometry>
      <material
        name="">
        <color
          rgba="0.0752941176470588 0.0752941176470588 0.0752941176470588 1" />
      </material>
    </visual>
    <collision>
      <origin
        xyz="0 0 0"
        rpy="3.14159 0 0" />
      <geometry>
        <mesh
          filename="package://ensamble_mobile/meshes/Link_1_1_wheel.STL" />
      </geometry>
    </collision>
  </link>
    <joint name="dummy_joint" type="fixed">
     <parent link="map"/>
     <child link="base_link_Chasis"/>
   </joint>
  <joint
    name="joint_rear_right"
    type="continuous">
    <origin
      xyz="-0.12 -0.13348 0.0195"
      rpy="1.5708 0 0" />
    <parent
      link="base_link_Chasis" />
    <child
      link="rear_right_wheel" />
    <axis
      xyz="0 0 -1" />
  </joint>
  <link
    name="rear_left_wheel">
    <inertial>
      <origin
        xyz="2.73809271632286E-06 -9.0341635872182E-07 -0.0321210915173856"
        rpy="0 0 0" />
      <mass
        value="0.62241947518931" />
      <inertia
        ixx="0.00062490065579211"
        ixy="3.60794637957165E-10"
        ixz="4.42299708533631E-09"
        iyy="0.00062490871616389"
        iyz="-2.56106433818635E-09"
        izz="0.00114905854450842" />
    </inertial>
    <visual>
      <origin
        xyz="0 0 0"
        rpy="0 0 0" />
      <geometry>
        <mesh
          filename="package://ensamble_mobile/meshes/Link_1_2_wheel.STL" />
      </geometry>
      <material
        name="">
        <color
          rgba="0.0752941176470588 0.0752941176470588 0.0752941176470588 1" />
      </material>
    </visual>
    <collision>
      <origin
        xyz="0 0 0"
        rpy="0 0 0" />
      <geometry>
        <mesh
          filename="package://ensamble_mobile/meshes/Link_1_2_wheel.STL" />
      </geometry>
    </collision>
  </link>
  <joint
    name="joint_rear_left"
    type="continuous">
    <origin
      xyz="-0.12 0.196084149285149 0.019499999999999"
      rpy="-1.5707963267949 0 0" />
    <parent
      link="base_link_Chasis" />
    <child
      link="rear_left_wheel" />
    <axis
      xyz="0 0 1" />
  </joint>
  <link
    name="front_right_wheel">
    <inertial>
      <origin
        xyz="2.45343850485691E-06 1.51457992322857E-06 -0.0304872070529117"
        rpy="3.14159 0 0" />
      <mass
        value="0.622419475189312" />
      <inertia
        ixx="0.00062490125347859"
        ixy="-2.14254962013106E-09"
        ixz="-3.70732769567224E-09"
        iyy="0.000624908118477413"
        iyz="-3.51819202590978E-09"
        izz="0.00114905854450842" />
    </inertial>
    <visual>
      <origin
        xyz="0 0 0"
        rpy="3.14159 0 0" />
      <geometry>
        <mesh
          filename="package://ensamble_mobile/meshes/Link_1_3_wheel.STL" />
      </geometry>
      <material
        name="">
        <color
          rgba="0.0752941176470588 0.0752941176470588 0.0752941176470588 1" />
      </material>
    </visual>
    <collision>
      <origin
        xyz="0 0 0"
        rpy="3.14159 0 0" />
      <geometry>
        <mesh
          filename="package://ensamble_mobile/meshes/Link_1_3_wheel.STL" />
      </geometry>
    </collision>
  </link>
  <joint
    name="joint_front_right"
    type="continuous">
    <origin
      xyz="0.0800000000000007 -0.133475850714851 0.0195000000000001"
      rpy="1.5707963267949 0 0" />
    <parent
      link="base_link_Chasis" />
    <child
      link="front_right_wheel" />
    <axis
      xyz="0 0 -1" />
  </joint>
  <link
    name="front_left_wheel">
    <inertial>
      <origin
        xyz="6.88887376004699E-07 2.79977624520478E-06 -0.0321210915173857"
        rpy="0 0 0" />
      <mass
        value="0.622419475189308" />
      <inertia
        ixx="0.000624908723580364"
        ixy="2.6521354361954E-10"
        ixz="2.21122175098438E-09"
        iyy="0.000624900648375635"
        iyz="4.60786850205311E-09"
        izz="0.00114905854450842" />
    </inertial>
    <visual>
      <origin
        xyz="0 0 0"
        rpy="0 0 0" />
      <geometry>
        <mesh
          filename="package://ensamble_mobile/meshes/Link_1_4_wheel.STL" />
      </geometry>
      <material
        name="">
        <color
          rgba="0.0752941176470588 0.0752941176470588 0.0752941176470588 1" />
      </material>
    </visual>
    <collision>
      <origin
        xyz="0 0 0"
        rpy="0 0 0" />
      <geometry>
        <mesh
          filename="package://ensamble_mobile/meshes/Link_1_4_wheel.STL" />
      </geometry>
    </collision>
  </link>
  <joint
    name="joint_front_left"
    type="continuous">
    <origin
      xyz="0.08 0.19608 0.0195"
      rpy="-1.5708 0 0" />
    <parent
      link="base_link_Chasis" />
    <child
      link="front_left_wheel" />
    <axis
      xyz="0 0 1" />
  </joint>
  
  <transmission name="transmission_rear_right">
    <type>transmission_interface/SimpleTransmission</type>
    <actuator name="motor_rear_right">
      <hardwareInterface>hardware_interface/EffortJointInterface</hardwareInterface>
      <mechanicalReduction>75</mechanicalReduction>
    </actuator>
    <joint name="joint_rear_right">
      <hardwareInterface>VelocityJointInterface</hardwareInterface>
    </joint>
  </transmission>
  <transmission name="transmission_rear_left">
    <type>transmission_interface/SimpleTransmission</type>
    <actuator name="motor_rear_left">
      <hardwareInterface>hardware_interface/EffortJointInterface</hardwareInterface>
      <mechanicalReduction>75</mechanicalReduction>
    </actuator>
    <joint name="joint_rear_left">
      <hardwareInterface>VelocityJointInterface</hardwareInterface>
    </joint>
  </transmission>
  <transmission name="transmission_front_right">
    <type>transmission_interface/SimpleTransmission</type>
    <actuator name="motor_front_right">
      <hardwareInterface>hardware_interface/EffortJointInterface</hardwareInterface>
      <mechanicalReduction>75</mechanicalReduction>
    </actuator>
    <joint name="joint_front_right">
      <hardwareInterface>VelocityJointInterface</hardwareInterface>
    </joint>
  </transmission>
  <transmission name="transmission_front_left">
    <type>transmission_interface/SimpleTransmission</type>
    <actuator name="motor_front_left">
      <hardwareInterface>hardware_interface/EffortJointInterface</hardwareInterface>
      <mechanicalReduction>75</mechanicalReduction>
    </actuator>
    <joint name="joint_front_left">
      <hardwareInterface>VelocityJointInterface</hardwareInterface>
    </joint>
  </transmission>

  
  <gazebo>
    <plugin name="gazebo_ros_control" filename="libgazebo_ros_control.so">
      <robotNamespace>/robot</robotNamespace>
      <robotSimType>gazebo_ros_control/DefaultRobotHWSim</robotSimType>
    </plugin>
  </gazebo>
  


  
</robot>